<?xml version="1.0"?>
<robot xmlns:xacro="http://ros.org/wiki/xacro">
  
  <xacro:macro name="lower_forearm" params="parent *joint_origin *joint_axis">
	<joint name="forearm_roll" type="revolute">
	  <xacro:insert_block name="joint_origin"/>
	  <parent link="${parent}"/>
	  <child link="lower_forearm_link"/>
          <limit effort="100" velocity="100" lower="-3.14" upper = "3.14"/>
          <dynamics damping="0.1" friction="0.1"/>
	  <xacro:insert_block name="joint_axis"/>
	</joint>

	<link name="lower_forearm_link">
	  <visual>
		  <geometry>
		    <mesh filename="package://wx250s_description/meshes/DAE/lower_forearm/lower_forearm.dae"/>
		  </geometry>
	  </visual>
	  <collision>
		  <geometry>
		    <mesh filename="package://wx250s_description/meshes/STL/lower_forearm/lower_forearm.stl"/>
		  </geometry>
	  </collision>
	  <inertial>
		<origin xyz="0.0374395000 0.0052225200 0"/>
		<mass value="0.220991"/>
		<inertia ixx="0.00006369" ixy="-0.00002292" ixz="0.0" iyy="0.0001677" iyz="0.0" izz="0.0001834"/>
	  </inertial>
          <surface>
            <friction>
              <ode>
                <mu1>1.2</mu1>
                <mu2>1.2</mu2>
                <kp>1e15</kp>
                <kd>1e13</kd>
              </ode>
            </friction>
            <bounce>
              <restitution_coefficient>0.01</restitution_coefficient>
              <threshold>0</threshold>
            </bounce>
            <contact>
              <ode>
                <max_vel>10</max_vel>
              </ode>
            </contact>
          </surface>
	</link>
  </xacro:macro>
  
</robot>
