<?xml version="1.0"?>
<robot xmlns:xacro="http://ros.org/wiki/xacro">
  
  <xacro:macro name="handle" params="parent *joint_origin *joint_axis">
	<joint name="handle_joint" type="revolute">
	  <xacro:insert_block name="joint_origin"/>
	  <parent link="${parent}"/>
	  <child link="handle_link"/>
          <limit effort="100" velocity="100" lower="-0.5" upper = "0.5"/>
          <dynamics damping="0.1" friction="0.1"/>
	  <xacro:insert_block name="joint_axis"/>
	</joint>

	<link name="handle_link">
	  <visual>
		  <geometry>
		    <mesh filename="package://wx250s_description/drawer_meshes/DAE/handle/handle.dae"/>
		  </geometry>
	  </visual>
	  <collision>
		  <geometry>
		    <mesh filename="package://wx250s_description/drawer_meshes/STL/handle/handle.stl"/>
		  </geometry>
	  </collision>
	  <inertial>
		<origin xyz="0.026 0.0 0.0"/>
		<mass value="0.012"/>
		<inertia ixx="0.0000246" ixy="-0.0000030658" ixz="0.0" iyy="0.000027754" iyz="0.0" izz="0.000003240"/>
	  </inertial>
          <surface>
            <friction>
              <ode>
                <mu1>1.2</mu1>
                <mu2>1.2</mu2>
                <kp>1e15</kp>
                <kd>1e13</kd>
              </ode>
            </friction>
            <bounce>
              <restitution_coefficient>0.01</restitution_coefficient>
              <threshold>0</threshold>
            </bounce>
            <contact>
              <ode>
                <max_vel>10</max_vel>
              </ode>
            </contact>
          </surface>
	</link>
  </xacro:macro>
  
</robot>
