<?xml version="1.0"?>
<robot xmlns:xacro="http://ros.org/wiki/xacro">
  
  <xacro:macro name="sholder" params="parent *joint_origin *joint_axis">
	<joint name="waist" type="revolute">
	  <xacro:insert_block name="joint_origin"/>
	  <parent link="${parent}"/>
	  <child link="sholder_link"/>
          <limit effort="100" velocity="100" lower="-3.14" upper = "3.14"/>
          <dynamics damping="0.1" friction="0.1"/>
	  <xacro:insert_block name="joint_axis"/>
	</joint>

	<link name="sholder_link">
	  <visual>
		  <geometry>
		    <mesh filename="package://wx250s_description/meshes/DAE/shoulder/shoulder.dae"/>
		  </geometry>
	  </visual>
	  <collision>
		  <geometry>
		    <mesh filename="package://wx250s_description/meshes/STL/shoulder/shoulder.stl"/>
		  </geometry>
	  </collision>
	  <inertial>
		<origin xyz="0.0000223482 0.0000414609 0.0066287000"/>
		<mass value="0.480879"/>
		<inertia ixx="0.222" ixy="0" ixz="0" iyy="0.395" iyz="0" izz="0.222"/>
	  </inertial>
          <surface>
            <friction>
              <ode>
                <mu1>1.2</mu1>
                <mu2>1.2</mu2>
                <kp>1e15</kp>
                <kd>1e13</kd>
              </ode>
            </friction>
            <bounce>
              <restitution_coefficient>0.01</restitution_coefficient>
              <threshold>0</threshold>
            </bounce>
            <contact>
              <ode>
                <max_vel>10</max_vel>
              </ode>
            </contact>
          </surface>
	</link>
  </xacro:macro>
  
</robot>
