<?xml version="1.0" ?>
<!-- =================================================================================== -->
<!-- |    This document was autogenerated by xacro from drawer_box.xacro               | -->
<!-- |    EDITING THIS FILE BY HAND IS NOT RECOMMENDED                                 | -->
<!-- =================================================================================== -->
<robot name="drawer">
  <link name="base_footprint"/>
  <joint name="base_link_joint" type="fixed">
    <origin rpy="1.57079637 0 0" xyz="0 0 0"/>
    <parent link="base_footprint"/>
    <child link="base_link"/>
  </joint>
  <link name="base_link">
    <visual>
      <geometry>
        <mesh filename="package://wx250s_description/drawer_meshes/DAE/box/box.dae"/>
      </geometry>
    </visual>
    <collision>
      <geometry>
        <mesh filename="package://wx250s_description/drawer_meshes/STL/box/box.stl"/>
      </geometry>
    </collision>
    <inertial>
      <origin xyz="-0.075 0.053 0"/>
      <mass value="0.89"/>
      <inertia ixx="0.0029" ixy="0.000061" ixz="0" iyy="0.0037" iyz="0" izz="0.00266"/>
    </inertial>
    <surface>
      <friction>
        <ode>
          <mu>0.8</mu>
          <mu2>0.8</mu2>
          <kp>1e15</kp>
          <kd>1e13</kd>
        </ode>
      </friction>
      <bounce>
        <restitution_coefficient>0.01</restitution_coefficient>
        <threshold>10</threshold>
      </bounce>
      <contact>
        <ode>
          <max_vel>0.01</max_vel>
          <minDepth>0</minDepth>
          <contact_surface_layer>0</contact_surface_layer>
        </ode>
      </contact>
    </surface>
  </link>
  <joint name="drawer_joint" type="prismatic">
    <origin rpy="0 0 0" xyz="0.01 0.0 0.0"/>
    <parent link="base_link"/>
    <child link="drawer_link"/>
    <limit effort="100" lower="0" upper="0.12" velocity="100"/>
    <dynamics damping="0.1" friction="0.1"/>
    <axis xyz="1 0 0"/>
  </joint>
  <link name="drawer_link">
    <visual>
      <geometry>
        <mesh filename="package://wx250s_description/drawer_meshes/DAE/drawer/drawer.dae"/>
      </geometry>
    </visual>
    <collision>
      <geometry>
        <mesh filename="package://wx250s_description/drawer_meshes/STL/drawer/drawer.stl"/>
      </geometry>
    </collision>
    <inertial>
      <origin xyz="-0.06286 0.0033 0.0"/>
      <mass value="0.4"/>
      <inertia ixx="0.000889" ixy="0.0000217" ixz="0" iyy="0.00176" iyz="0" izz="0.00120"/>
    </inertial>
    <surface>
      <friction>
        <ode>
          <mu1>0.1</mu1>
          <mu2>0.1</mu2>
          <kp>1e15</kp>
          <kd>1e13</kd>
        </ode>
      </friction>
      <bounce>
        <restitution_coefficient>0.01</restitution_coefficient>
        <threshold>0</threshold>
      </bounce>
      <contact>
        <ode>
          <max_vel>10</max_vel>
        </ode>
      </contact>
    </surface>
  </link>
  <joint name="handle_joint" type="revolute">
    <origin rpy="0 0 0" xyz="0.00425 0.04 0.0"/>
    <parent link="drawer_link"/>
    <child link="handle_link"/>
    <limit effort="100" lower="-0.5" upper="0.5" velocity="100"/>
    <dynamics damping="0.1" friction="0.1"/>
    <axis xyz="0 0 1"/>
  </joint>
  <link name="handle_link">
    <visual>
      <geometry>
        <mesh filename="package://wx250s_description/drawer_meshes/DAE/handle/handle.dae"/>
      </geometry>
    </visual>
    <collision>
      <geometry>
        <mesh filename="package://wx250s_description/drawer_meshes/STL/handle/handle.stl"/>
      </geometry>
    </collision>
    <inertial>
      <origin xyz="0.026 0.0 0.0"/>
      <mass value="0.012"/>
      <inertia ixx="0.0000246" ixy="-0.0000030658" ixz="0.0" iyy="0.000027754" iyz="0.0" izz="0.000003240"/>
    </inertial>
    <surface>
      <friction>
        <ode>
          <mu1>1.2</mu1>
          <mu2>1.2</mu2>
          <kp>1e15</kp>
          <kd>1e13</kd>
        </ode>
      </friction>
      <bounce>
        <restitution_coefficient>0.01</restitution_coefficient>
        <threshold>0</threshold>
      </bounce>
      <contact>
        <ode>
          <max_vel>10</max_vel>
        </ode>
      </contact>
    </surface>
  </link>
</robot>
